Traceback (most recent call last):
  File "/home/ryan/.conda/envs/work3-10/lib/python3.10/site-packages/jupyter_cache/executors/utils.py", line 58, in single_nb_execution
    executenb(
  File "/home/ryan/.conda/envs/work3-10/lib/python3.10/site-packages/nbclient/client.py", line 1305, in execute
    return NotebookClient(nb=nb, resources=resources, km=km, **kwargs).execute()
  File "/home/ryan/.conda/envs/work3-10/lib/python3.10/site-packages/jupyter_core/utils/__init__.py", line 165, in wrapped
    return loop.run_until_complete(inner)
  File "/home/ryan/.conda/envs/work3-10/lib/python3.10/asyncio/base_events.py", line 649, in run_until_complete
    return future.result()
  File "/home/ryan/.conda/envs/work3-10/lib/python3.10/site-packages/nbclient/client.py", line 705, in async_execute
    await self.async_execute_cell(
  File "/home/ryan/.conda/envs/work3-10/lib/python3.10/site-packages/nbclient/client.py", line 1058, in async_execute_cell
    await self._check_raise_for_error(cell, cell_index, exec_reply)
  File "/home/ryan/.conda/envs/work3-10/lib/python3.10/site-packages/nbclient/client.py", line 914, in _check_raise_for_error
    raise CellExecutionError.from_cell_and_msg(cell, exec_reply_content)
nbclient.exceptions.CellExecutionError: An error occurred while executing the following cell:
------------------
import numpy as np
import matplotlib.pyplot as plt
plt.style.use('fivethirtyeight')
import pandas as pd
------------------


[0;31m---------------------------------------------------------------------------[0m
[0;31mImportError[0m                               Traceback (most recent call last)
File [0;32m~/.local/lib/python3.10/site-packages/numpy/core/__init__.py:22[0m
[1;32m     21[0m [38;5;28;01mtry[39;00m:
[0;32m---> 22[0m     [38;5;28;01mfrom[39;00m [38;5;21;01m.[39;00m [38;5;28;01mimport[39;00m multiarray
[1;32m     23[0m [38;5;28;01mexcept[39;00m [38;5;167;01mImportError[39;00m [38;5;28;01mas[39;00m exc:

File [0;32m~/.local/lib/python3.10/site-packages/numpy/core/multiarray.py:12[0m
[1;32m     10[0m [38;5;28;01mimport[39;00m [38;5;21;01mwarnings[39;00m
[0;32m---> 12[0m [38;5;28;01mfrom[39;00m [38;5;21;01m.[39;00m [38;5;28;01mimport[39;00m overrides
[1;32m     13[0m [38;5;28;01mfrom[39;00m [38;5;21;01m.[39;00m [38;5;28;01mimport[39;00m _multiarray_umath

File [0;32m~/.local/lib/python3.10/site-packages/numpy/core/overrides.py:7[0m
[1;32m      5[0m [38;5;28;01mimport[39;00m [38;5;21;01mtextwrap[39;00m
[0;32m----> 7[0m [38;5;28;01mfrom[39;00m [38;5;21;01mnumpy[39;00m[38;5;21;01m.[39;00m[38;5;21;01mcore[39;00m[38;5;21;01m.[39;00m[38;5;21;01m_multiarray_umath[39;00m [38;5;28;01mimport[39;00m (
[1;32m      8[0m     add_docstring, implement_array_function, _get_implementing_args)
[1;32m      9[0m [38;5;28;01mfrom[39;00m [38;5;21;01mnumpy[39;00m[38;5;21;01m.[39;00m[38;5;21;01mcompat[39;00m[38;5;21;01m.[39;00m[38;5;21;01m_inspect[39;00m [38;5;28;01mimport[39;00m getargspec

[0;31mImportError[0m: /home/ryan/.local/lib/python3.10/site-packages/numpy/core/_multiarray_umath.cpython-310-x86_64-linux-gnu.so: undefined symbol: cblas_sgemm

During handling of the above exception, another exception occurred:

[0;31mImportError[0m                               Traceback (most recent call last)
Cell [0;32mIn[1], line 1[0m
[0;32m----> 1[0m [38;5;28;01mimport[39;00m [38;5;21;01mnumpy[39;00m [38;5;28;01mas[39;00m [38;5;21;01mnp[39;00m
[1;32m      2[0m [38;5;28;01mimport[39;00m [38;5;21;01mmatplotlib[39;00m[38;5;21;01m.[39;00m[38;5;21;01mpyplot[39;00m [38;5;28;01mas[39;00m [38;5;21;01mplt[39;00m
[1;32m      3[0m plt[38;5;241m.[39mstyle[38;5;241m.[39muse([38;5;124m'[39m[38;5;124mfivethirtyeight[39m[38;5;124m'[39m)

File [0;32m~/.local/lib/python3.10/site-packages/numpy/__init__.py:150[0m
[1;32m    147[0m [38;5;66;03m# Allow distributors to run custom init code[39;00m
[1;32m    148[0m [38;5;28;01mfrom[39;00m [38;5;21;01m.[39;00m [38;5;28;01mimport[39;00m _distributor_init
[0;32m--> 150[0m [38;5;28;01mfrom[39;00m [38;5;21;01m.[39;00m [38;5;28;01mimport[39;00m core
[1;32m    151[0m [38;5;28;01mfrom[39;00m [38;5;21;01m.[39;00m[38;5;21;01mcore[39;00m [38;5;28;01mimport[39;00m [38;5;241m*[39m
[1;32m    152[0m [38;5;28;01mfrom[39;00m [38;5;21;01m.[39;00m [38;5;28;01mimport[39;00m compat

File [0;32m~/.local/lib/python3.10/site-packages/numpy/core/__init__.py:48[0m
[1;32m     24[0m     [38;5;28;01mimport[39;00m [38;5;21;01msys[39;00m
[1;32m     25[0m     msg [38;5;241m=[39m [38;5;124m"""[39m
[1;32m     26[0m 
[1;32m     27[0m [38;5;124mIMPORTANT: PLEASE READ THIS FOR ADVICE ON HOW TO SOLVE THIS ISSUE![39m
[0;32m   (...)[0m
[1;32m     46[0m [38;5;124m"""[39m [38;5;241m%[39m (sys[38;5;241m.[39mversion_info[[38;5;241m0[39m], sys[38;5;241m.[39mversion_info[[38;5;241m1[39m], sys[38;5;241m.[39mexecutable,
[1;32m     47[0m         __version__, exc)
[0;32m---> 48[0m     [38;5;28;01mraise[39;00m [38;5;167;01mImportError[39;00m(msg)
[1;32m     49[0m [38;5;28;01mfinally[39;00m:
[1;32m     50[0m     [38;5;28;01mfor[39;00m envkey [38;5;129;01min[39;00m env_added:

[0;31mImportError[0m: 

IMPORTANT: PLEASE READ THIS FOR ADVICE ON HOW TO SOLVE THIS ISSUE!

Importing the numpy C-extensions failed. This error can happen for
many reasons, often due to issues with your setup or how NumPy was
installed.

We have compiled some common reasons and troubleshooting tips at:

    https://numpy.org/devdocs/user/troubleshooting-importerror.html

Please note and check the following:

  * The Python version is: Python3.10 from "/home/ryan/.conda/envs/work3-10/bin/python"
  * The NumPy version is: "1.21.1"

and make sure that they are the versions you expect.
Please carefully study the documentation linked above for further help.

Original error was: /home/ryan/.local/lib/python3.10/site-packages/numpy/core/_multiarray_umath.cpython-310-x86_64-linux-gnu.so: undefined symbol: cblas_sgemm


